Workbook

Sheet Main Data
A1: Transaction ID | B1: Date | C1: Sales Rep | D1: Branch Code | E1: Region | F1: Product | G1: Lead Source | H1: Customer Segment | I1: Customer Age | J1: Account Tenure Months | K1: Revenue | L1: Processing Fee | M1: Discount Applied | N1: Target Achieved | O1: CSAT Score
A2: TRX-10000 | B2: 46088 | C2: Jamie | D2: BR-006 | E2: East | F2: Wealth Management | G2: Walk-in | H2: Retail | I2: 74 | J2: 16 | K2: 25114.07 | L2: 350.3 | M2: 179.26 | N2: No | O2: 4
A3: TRX-10001 | B3: 46007 | C3: Morgan | D3: BR-015 | E3: South | F3: Personal Loan | G3: Website | H3: High Net Worth | I3: 28 | J3: 28 | K3: 9331.6 | L3: 106.51 | M3: 121.35 | N3: Yes | O3: 5
A4: TRX-10002 | B4: 45886 | C4: Casey | D4: BR-001 | E4: East | F4: Auto Loan | G4: Social Media | H4: High Net Worth | I4: 44 | J4: 112 | K4: 5853.67 | L4: 394.49 | M4: 136.7 | N4: Yes | O4: 5
A5: TRX-10003 | B5: 46015 | C5: Jamie | D5: BR-009 | E5: Central | F5: Mortgage | G5: Website | H5: Retail | I5: 35 | J5: 35 | K5: 42184.29 | L5: 144.59 | M5: 141.15 | N5: Yes | O5: 5
A6: TRX-10004 | B6: 45980 | C6: Taylor | D6: BR-001 | E6: South | F6: Auto Loan | G6: Website | H6: High Net Worth | I6: 63 | J6: 60 | K6: 30899.59 | L6: 195.55 | M6: 246.26 | N6: No | O6: 1
A7: TRX-10005 | B7: 46170 | C7: Drew | D7: BR-005 | E7: West | F7: Mortgage | G7: Walk-in | H7: High Net Worth | I7: 51 | J7: 45 | K7: 16628.32 | L7: 418.66 | M7: 70.9 | N7: No | O7: 5
A8: TRX-10006 | B8: 46132 | C8: Casey | D8: BR-004 | E8: East | F8: Mortgage | G8: Website | H8: Retail | I8: 29 | J8: 46 | K8: 9990.94 | L8: 291.44 | M8: 132.27 | N8: Yes | O8: 4
A9: TRX-10007 | B9: 46226 | C9: Casey | D9: BR-013 | E9: South | F9: Auto Loan | G9: Walk-in | H9: Retail | I9: 59 | J9: 72 | K9: 27997.12 | L9: 436.97 | M9: 78.4 | N9: Yes | O9: 2
A10: TRX-10008 | B10: 46066 | C10: Jamie | D10: BR-012 | E10: East | F10: Mortgage | G10: Social Media | H10: Corporate | I10: 65 | J10: 108 | K10: 29404 | L10: 145.87 | M10: 73.74 | N10: No | O10: 5
A11: TRX-10009 | B11: 46230 | C11: Jordan | D11: BR-013 | E11: South | F11: Mortgage | G11: Email Campaign | H11: SME | I11: 22 | J11: 55 | K11: 10746.18 | L11: 323.5 | M11: 138.01 | N11: Yes | O11: 2
A12: TRX-10010 | B12: 45945 | C12: Taylor | D12: BR-013 | E12: North | F12: Personal Loan | G12: Walk-in | H12: SME | I12: 28 | J12: 119 | K12: 42644.58 | L12: 87.71 | M12: 77.44 | N12: Yes | O12: 4
A13: TRX-10011 | B13: 46203 | C13: Jamie | D13: BR-014 | E13: East | F13: Wealth Management | G13: Social Media | H13: Retail | I13: 27 | J13: 86 | K13: 4671.09 | L13: 339.38 | M13: 69.22 | N13: Yes | O13: 5
... A1001: TRX-10999 | B1001: 46151 | C1001: Taylor | D1001: BR-009 | E1001: West | F1001: Credit Card | G1001: Website | H1001: Corporate | I1001: 42 | J1001: 6 | K1001: 40998.21 | L1001: 121.83 | M1001: 111.97 | N1001: Yes | O1001: 4

Sheet Double lookup
A1: DOUBLE VLOOKUP
A3: Transaction ID | B3: Branch Code | C3: Date | D3: Sales Rep | E3: Region | F3: Product | G3: Lead Source | H3: Customer Segment | I3: Customer Age | J3: Account Tenure Months | K3: Revenue | L3: Processing Fee | M3: Discount Applied | N3: Target Achieved | O3: CSAT Score
A4: TRX-10000 | B4: =VLOOKUP($A$4,A7:B1007,2,0) -> BR-006 | C4: {=VLOOKUP(VLOOKUP($A$4,A7:B1007,2,0),$E$7:$R$1007,{2,3,4,5,6,7,8,9,10,11,12,13,14},0)} -> 46088 | D4: Jamie | E4: East | F4: Wealth Management | G4: Walk-in | H4: Retail | I4: 74 | J4: 16 | K4: 25114.07 | L4: 350.3 | M4: 179.26 | N4: No | O4: 4
A7: Transaction ID | B7: Branch Code | E7: Branch Code | F7: Date | G7: Sales Rep | H7: Region | I7: Product | J7: Lead Source | K7: Customer Segment | L7: Customer Age | M7: Account Tenure Months | N7: Revenue | O7: Processing Fee | P7: Discount Applied | Q7: Target Achieved | R7: CSAT Score
A8: TRX-10000 | B8: BR-006 | E8: BR-006 | F8: 46088 | G8: Jamie | H8: East | I8: Wealth Management | J8: Walk-in | K8: Retail | L8: 74 | M8: 16 | N8: 25114.07 | O8: 350.3 | P8: 179.26 | Q8: No | R8: 4
A9: TRX-10001 | B9: BR-015 | E9: BR-015 | F9: 46007 | G9: Morgan | H9: South | I9: Personal Loan | J9: Website | K9: High Net Worth | L9: 28 | M9: 28 | N9: 9331.6 | O9: 106.51 | P9: 121.35 | Q9: Yes | R9: 5
A10: TRX-10002 | B10: BR-001 | E10: BR-001 | F10: 45886 | G10: Casey | H10: East | I10: Auto Loan | J10: Social Media | K10: High Net Worth | L10: 44 | M10: 112 | N10: 5853.67 | O10: 394.49 | P10: 136.7 | Q10: Yes | R10: 5
A11: TRX-10003 | B11: BR-009 | E11: BR-009 | F11: 46015 | G11: Jamie | H11: Central | I11: Mortgage | J11: Website | K11: Retail | L11: 35 | M11: 35 | N11: 42184.29 | O11: 144.59 | P11: 141.15 | Q11: Yes | R11: 5
A12: TRX-10004 | B12: BR-001 | E12: BR-001 | F12: 45980 | G12: Taylor | H12: South | I12: Auto Loan | J12: Website | K12: High Net Worth | L12: 63 | M12: 60 | N12: 30899.59 | O12: 195.55 | P12: 246.26 | Q12: No | R12: 1
A13: TRX-10005 | B13: BR-005 | E13: BR-005 | F13: 46170 | G13: Drew | H13: West | I13: Mortgage | J13: Walk-in | K13: High Net Worth | L13: 51 | M13: 45 | N13: 16628.32 | O13: 418.66 | P13: 70.9 | Q13: No | R13: 5
A14: TRX-10006 | B14: BR-004 | E14: BR-004 | F14: 46132 | G14: Casey | H14: East | I14: Mortgage | J14: Website | K14: Retail | L14: 29 | M14: 46 | N14: 9990.94 | O14: 291.44 | P14: 132.27 | Q14: Yes | R14: 4
A15: TRX-10007 | B15: BR-013 | E15: BR-013 | F15: 46226 | G15: Casey | H15: South | I15: Auto Loan | J15: Walk-in | K15: Retail | L15: 59 | M15: 72 | N15: 27997.12 | O15: 436.97 | P15: 78.4 | Q15: Yes | R15: 2
A16: TRX-10008 | B16: BR-012 | E16: BR-012 | F16: 46066 | G16: Jamie | H16: East | I16: Mortgage | J16: Social Media | K16: Corporate | L16: 65 | M16: 108 | N16: 29404 | O16: 145.87 | P16: 73.74 | Q16: No | R16: 5
A17: TRX-10009 | B17: BR-013 | E17: BR-013 | F17: 46230 | G17: Jordan | H17: South | I17: Mortgage | J17: Email Campaign | K17: SME | L17: 22 | M17: 55 | N17: 10746.18 | O17: 323.5 | P17: 138.01 | Q17: Yes | R17: 2
A18: TRX-10010 | B18: BR-013 | E18: BR-013 | F18: 45945 | G18: Taylor | H18: North | I18: Personal Loan | J18: Walk-in | K18: SME | L18: 28 | M18: 119 | N18: 42644.58 | O18: 87.71 | P18: 77.44 | Q18: Yes | R18: 4
A19: TRX-10011 | B19: BR-014 | E19: BR-014 | F19: 46203 | G19: Jamie | H19: East | I19: Wealth Management | J19: Social Media | K19: Retail | L19: 27 | M19: 86 | N19: 4671.09 | O19: 339.38 | P19: 69.22 | Q19: Yes | R19: 5
... A1007: TRX-10999 | B1007: BR-009 | E1007: BR-009 | F1007: 46151 | G1007: Taylor | H1007: West | I1007: Credit Card | J1007: Website | K1007: Corporate | L1007: 42 | M1007: 6 | N1007: 40998.21 | O1007: 121.83 | P1007: 111.97 | Q1007: Yes | R1007: 4

Sheet Dynamic Lookup Function
A1: DYNAMIC TWO WAY GRID SEARCH
A3: Transaction ID | B3: Branch Code | C3: Date | D3: Sales Rep | E3: Region | F3: Product | G3: Lead Source | H3: Customer Segment | I3: Customer Age | J3: Account Tenure Months | K3: Revenue | L3: Processing Fee | M3: Discount Applied | N3: Target Achieved | O3: CSAT Score | Q3: Branch Code
A4: TRX-10000 | B4: BR-006 | C4: 46088 | D4: Jamie | E4: East | F4: Wealth Management | G4: Walk-in | H4: Retail | I4: 74 | J4: 16 | K4: 25114.07 | L4: 350.3 | M4: 179.26 | N4: No | O4: 4
A5: TRX-10001 | B5: BR-015 | C5: 46007 | D5: Morgan | E5: South | F5: Personal Loan | G5: Website | H5: High Net Worth | I5: 28 | J5: 28 | K5: 9331.6 | L5: 106.51 | M5: 121.35 | N5: Yes | O5: 5 | Q5: BR-006
A6: TRX-10002 | B6: BR-001 | C6: 45886 | D6: Casey | E6: East | F6: Auto Loan | G6: Social Media | H6: High Net Worth | I6: 44 | J6: 112 | K6: 5853.67 | L6: 394.49 | M6: 136.7 | N6: Yes | O6: 5
A7: TRX-10003 | B7: BR-009 | C7: 46015 | D7: Jamie | E7: Central | F7: Mortgage | G7: Website | H7: Retail | I7: 35 | J7: 35 | K7: 42184.29 | L7: 144.59 | M7: 141.15 | N7: Yes | O7: 5 | Q7: Sales Rep | R7: Region | S7: Product | T7: Lead Source | U7: Customer Segment | V7: Account Tenure Months | W7: Revenue
A8: TRX-10004 | B8: BR-001 | C8: 45980 | D8: Taylor | E8: South | F8: Auto Loan | G8: Website | H8: High Net Worth | I8: 63 | J8: 60 | K8: 30899.59 | L8: 195.55 | M8: 246.26 | N8: No | O8: 1 | Q8: {=IFERROR(VLOOKUP(Q5,$A$3:$O$1003,{4,5,6,7,8,10,11},0),VLOOKUP(Q5,$B$3:$O$1003,{3,4,5,6,7,9,10},0))} -> Jamie | R8: East | S8: Wealth Management | T8: Walk-in | U8: Retail | V8: 16 | W8: 25114.07
A9: TRX-10005 | B9: BR-005 | C9: 46170 | D9: Drew | E9: West | F9: Mortgage | G9: Walk-in | H9: High Net Worth | I9: 51 | J9: 45 | K9: 16628.32 | L9: 418.66 | M9: 70.9 | N9: No | O9: 5
A10: TRX-10006 | B10: BR-004 | C10: 46132 | D10: Casey | E10: East | F10: Mortgage | G10: Website | H10: Retail | I10: 29 | J10: 46 | K10: 9990.94 | L10: 291.44 | M10: 132.27 | N10: Yes | O10: 4
A11: TRX-10007 | B11: BR-013 | C11: 46226 | D11: Casey | E11: South | F11: Auto Loan | G11: Walk-in | H11: Retail | I11: 59 | J11: 72 | K11: 27997.12 | L11: 436.97 | M11: 78.4 | N11: Yes | O11: 2
A12: TRX-10008 | B12: BR-012 | C12: 46066 | D12: Jamie | E12: East | F12: Mortgage | G12: Social Media | H12: Corporate | I12: 65 | J12: 108 | K12: 29404 | L12: 145.87 | M12: 73.74 | N12: No | O12: 5
A13: TRX-10009 | B13: BR-013 | C13: 46230 | D13: Jordan | E13: South | F13: Mortgage | G13: Email Campaign | H13: SME | I13: 22 | J13: 55 | K13: 10746.18 | L13: 323.5 | M13: 138.01 | N13: Yes | O13: 2
A14: TRX-10010 | B14: BR-013 | C14: 45945 | D14: Taylor | E14: North | F14: Personal Loan | G14: Walk-in | H14: SME | I14: 28 | J14: 119 | K14: 42644.58 | L14: 87.71 | M14: 77.44 | N14: Yes | O14: 4
A15: TRX-10011 | B15: BR-014 | C15: 46203 | D15: Jamie | E15: East | F15: Wealth Management | G15: Social Media | H15: Retail | I15: 27 | J15: 86 | K15: 4671.09 | L15: 339.38 | M15: 69.22 | N15: Yes | O15: 5
A16: TRX-10012 | B16: BR-003 | C16: 46076 | D16: Taylor | E16: West | F16: Wealth Management | G16: Email Campaign | H16: Retail | I16: 64 | J16: 85 | K16: 18126.61 | L16: 393.14 | M16: 167.18 | N16: No | O16: 1
A17: TRX-10013 | B17: BR-013 | C17: 45927 | D17: Taylor | E17: West | F17: Personal Loan | G17: Referral | H17: High Net Worth | I17: 71 | J17: 26 | K17: 34179.03 | L17: 313.22 | M17: 30.39 | N17: Yes | O17: 1
A18: TRX-10014 | B18: BR-006 | C18: 46137 | D18: Drew | E18: Central | F18: Auto Loan | G18: Walk-in | H18: Corporate | I18: 59 | J18: 104 | K18: 14068.96 | L18: 169.8 | M18: 135.18 | N18: No | O18: 2
A19: TRX-10015 | B19: BR-002 | C19: 46208 | D19: Casey | E19: South | F19: Credit Card | G19: Walk-in | H19: Corporate | I19: 62 | J19: 85 | K19: 41469.92 | L19: 64.1 | M19: 49.75 | N19: Yes | O19: 1
A20: TRX-10016 | B20: BR-003 | C20: 46029 | D20: Morgan | E20: East | F20: Credit Card | G20: Referral | H20: Retail | I20: 36 | J20: 25 | K20: 37123.46 | L20: 103.75 | M20: 3.1 | N20: No | O20: 1
... A1003: TRX-10999 | B1003: BR-009 | C1003: 46151 | D1003: Taylor | E1003: West | F1003: Credit Card | G1003: Website | H1003: Corporate | I1003: 42 | J1003: 6 | K1003: 40998.21 | L1003: 121.83 | M1003: 111.97 | N1003: Yes | O1003: 4

Sheet Vlookup
A1: VLOOKUP
A5: Transaction ID | B5: Date | C5: Sales Rep | D5: Branch Code | E5: Region | F5: Product | G5: Lead Source | H5: Customer Segment | I5: Customer Age | J5: Account Tenure Months | K5: Revenue | L5: Processing Fee | M5: Discount Applied | N5: Target Achieved | O5: CSAT Score
A6: TRX-10000 | B6: {=VLOOKUP($A$6,'Main Data'!A1:O1001,{2,3,4,5,6,7,8,9,10,11,12,13,14,15},0)} -> 46088 | C6: Jamie | D6: BR-006 | E6: East | F6: Wealth Management | G6: Walk-in | H6: Retail | I6: 74 | J6: 16 | K6: 25114.07 | L6: 350.3 | M6: 179.26 | N6: No | O6: 4

Sheet Hlookup
A1: Transaction ID | B1: TRX-10000 | C1: TRX-10001 | D1: TRX-10002 | E1: TRX-10003 | F1: TRX-10004 | G1: TRX-10005 | H1: TRX-10006 | I1: TRX-10007 | J1: TRX-10008 | K1: TRX-10009 | L1: TRX-10010 | M1: TRX-10011 | N1: TRX-10012 | O1: TRX-10013 | P1: TRX-10014 | Q1: TRX-10015 | R1: TRX-10016 | S1: TRX-10017 | T1: TRX-10018 | U1: TRX-10019 | V1: TRX-10020 | W1: TRX-10021 | X1: TRX-10022 | Y1: TRX-10023 | Z1: TRX-10024 | AA1: TRX-10025 | AB1: TRX-10026 | AC1: TRX-10027 | AD1: TRX-10028 | AE1: TRX-10029 | AF1: TRX-10030 | AG1: TRX-10031 | AH1: TRX-10032 | AI1: TRX-10033 | AJ1: TRX-10034 | AK1: TRX-10035 | AL1: TRX-10036 | AM1: TRX-10037 | AN1: TRX-10038 | AO1: TRX-10039 | AP1: TRX-10040 | AQ1: TRX-10041 | AR1: TRX-10042 | AS1: TRX-10043 | AT1: TRX-10044 | AU1: TRX-10045 | AV1: TRX-10046 | AW1: TRX-10047 | AX1: TRX-10048 | AY1: TRX-10049 | AZ1: TRX-10050 | BA1: TRX-10051 | BB1: TRX-10052 | BC1: TRX-10053 | BD1: TRX-10054 | BE1: TRX-10055 | BF1: TRX-10056 | BG1: TRX-10057 | BH1: TRX-10058 | BI1: TRX-10059 | BJ1: TRX-10060 | BK1: TRX-10061 | BL1: TRX-10062 | BM1: TRX-10063 | BN1: TRX-10064 | BO1: TRX-10065 | BP1: TRX-10066 | BQ1: TRX-10067 | BR1: TRX-10068 | BS1: TRX-10069 | BT1: TRX-10070 | BU1: TRX-10071 | BV1: TRX-10072 | BW1: TRX-10073 | BX1: TRX-10074 | BY1: TRX-10075 | BZ1: TRX-10076 | CA1: TRX-10077 | CB1: TRX-10078 | CC1: TRX-10079 | CD1: TRX-10080 | CE1: TRX-10081 | CF1: TRX-10082 | CG1: TRX-10083 | CH1: TRX-10084 | CI1: TRX-10085 | CJ1: TRX-10086 | CK1: TRX-10087 | CL1: TRX-10088 | CM1: TRX-10089 | CN1: TRX-10090 | CO1: TRX-10091 | CP1: TRX-10092 | CQ1: TRX-10093 | CR1: TRX-10094 | CS1: TRX-10095 | CT1: TRX-10096 | CU1: TRX-10097 | CV1: TRX-10098 | CW1: TRX-10099 | CX1: TRX-10100 | CY1: TRX-10101 | CZ1: TRX-10102 | DA1: TRX-10103 | DB1: TRX-10104 | DC1: TRX-10105 | DD1: TRX-10106 | DE1: TRX-10107 | DF1: TRX-10108 | DG1: TRX-10109 | DH1: TRX-10110 | DI1: TRX-10111 | DJ1: TRX-10112 | DK1: TRX-10113 | DL1: TRX-10114 | DM1: TRX-10115 | DN1: TRX-10116 | DO1: TRX-10117 | DP1: TRX-10118 | DQ1: TRX-10119 | DR1: TRX-10120 | DS1: TRX-10121 | DT1: TRX-10122 | DU1: TRX-10123 | DV1: TRX-10124 | DW1: TRX-10125 | DX1: TRX-10126 | DY1: TRX-10127 | DZ1: TRX-10128 | EA1: TRX-10129 | EB1: TRX-10130 | EC1: TRX-10131 | ED1: TRX-10132 | EE1: TRX-10133 | EF1: TRX-10134 | EG1: TRX-10135 | EH1: TRX-10136 | EI1: TRX-10137 | EJ1: TRX-10138 | EK1: TRX-10139 | EL1: TRX-10140 | EM1: TRX-10141 | EN1: TRX-10142 | EO1: TRX-10143 | EP1: TRX-10144 | EQ1: TRX-10145 | ER1: TRX-10146 | ES1: TRX-10147 | ET1: TRX-10148 | EU1: TRX-10149 | EV1: TRX-10150 | EW1: TRX-10151 | EX1: TRX-10152 | EY1: TRX-10153 | EZ1: TRX-10154 | FA1: TRX-10155 | FB1: TRX-10156 | FC1: TRX-10157 | FD1: TRX-10158 | FE1: TRX-10159 | FF1: TRX-10160 | FG1: TRX-10161 | FH1: TRX-10162 | FI1: TRX-10163 | FJ1: TRX-10164 | FK1: TRX-10165 | FL1: TRX-10166 | FM1: TRX-10167 | FN1: TRX-10168 | FO1: TRX-10169 | FP1: TRX-10170 | FQ1: TRX-10171 | FR1: TRX-10172 | FS1: TRX-10173 | FT1: TRX-10174 | FU1: TRX-10175 | FV1: TRX-10176 | FW1: TRX-10177 | FX1: TRX-10178 | FY1: TRX-10179 | FZ1: TRX-10180 | GA1: TRX-10181 | GB1: TRX-10182 | GC1: TRX-10183 | GD1: TRX-10184 | GE1: TRX-10185 | GF1: TRX-10186 | GG1: TRX-10187 | GH1: TRX-10188 | GI1: TRX-10189 | GJ1: TRX-10190 | GK1: TRX-10191 | GL1: TRX-10192 | GM1: TRX-10193 | GN1: TRX-10194 | GO1: TRX-10195 | GP1: TRX-10196 | GQ1: TRX-10197 | GR1: TRX-10198 | GS1: TRX-10199 | GT1: TRX-10200 | GU1: TRX-10201 | GV1: TRX-10202 | GW1: TRX-10203 | GX1: TRX-10204 | GY1: TRX-10205 | GZ1: TRX-10206 | HA1: TRX-10207 | HB1: TRX-10208 | HC1: TRX-10209 | HD1: TRX-10210 | HE1: TRX-10211 | HF1: TRX-10212 | HG1: TRX-10213 | HH1: TRX-10214 | HI1: TRX-10215 | HJ1: TRX-10216 | HK1: TRX-10217 | HL1: TRX-10218 | HM1: TRX-10219 | HN1: TRX-10220 | HO1: TRX-10221 | HP1: TRX-10222 | HQ1: TRX-10223 | HR1: TRX-10224 | HS1: TRX-10225 | HT1: TRX-10226 | HU1: TRX-10227 | HV1: TRX-10228 | HW1: TRX-10229 | HX1: TRX-10230 | HY1: TRX-10231 | HZ1: TRX-10232 | IA1: TRX-10233 | IB1: TRX-10234 | IC1: TRX-10235 | ID1: TRX-10236 | IE1: TRX-10237 | IF1: TRX-10238 | IG1: TRX-10239 | IH1: TRX-10240 | II1: TRX-10241 | IJ1: TRX-10242 | IK1: TRX-10243 | IL1: TRX-10244 | IM1: TRX-10245 | IN1: TRX-10246 | IO1: TRX-10247 | IP1: TRX-10248 | IQ1: TRX-10249 | IR1: TRX-10250 | IS1: TRX-10251 | IT1: TRX-10252 | IU1: TRX-10253 | IV1: TRX-10254 | IW1: TRX-10255 | IX1: TRX-10256 | IY1: TRX-10257 | IZ1: TRX-10258 | JA1: TRX-10259 | JB1: TRX-10260 | JC1: TRX-10261 | JD1: TRX-10262 | JE1: TRX-10263 | JF1: TRX-10264 | JG1: TRX-10265 | JH1: TRX-10266 | JI1: TRX-10267 | JJ1: TRX-10268 | JK1: TRX-10269 | JL1: TRX-10270 | JM1: TRX-10271 | JN1: TRX-10272 | JO1: TRX-10273 | JP1: TRX-10274 | JQ1: TRX-10275 | JR1: TRX-10276 | JS1: TRX-10277 | JT1: TRX-10278 | JU1: TRX-10279 | JV1: TRX-10280 | JW1: TRX-10281 | JX1: TRX-10282 | JY1: TRX-10283 | JZ1: TRX-10284 | KA1: TRX-10285 | KB1: TRX-10286 | KC1: TRX-10287 | KD1: TRX-10288 | KE1: TRX-10289 | KF1: TRX-10290 | KG1: TRX-10291 | KH1: TRX-10292 | KI1: TRX-10293 | KJ1: TRX-10294 | KK1: TRX-10295 | KL1: TRX-10296 | KM1: TRX-10297 | KN1: TRX-10298 | KO1: TRX-10299 | KP1: TRX-10300 | KQ1: TRX-10301 | KR1: TRX-10302 | KS1: TRX-10303 | KT1: TRX-10304 | KU1: TRX-10305 | KV1: TRX-10306 | KW1: TRX-10307 | KX1: TRX-10308 | KY1: TRX-10309 | KZ1: TRX-10310 | LA1: TRX-10311 | LB1: TRX-10312 | LC1: TRX-10313 | LD1: TRX-10314 | LE1: TRX-10315 | LF1: TRX-10316 | LG1: TRX-10317 | LH1: TRX-10318 | LI1: TRX-10319 | LJ1: TRX-10320 | LK1: TRX-10321 | LL1: TRX-10322 | LM1: TRX-10323 | LN1: TRX-10324 | LO1: TRX-10325 | LP1: TRX-10326 | LQ1: TRX-10327 | LR1: TRX-10328 | LS1: TRX-10329 | LT1: TRX-10330 | LU1: TRX-10331 | LV1: TRX-10332 | LW1: TRX-10333 | LX1: TRX-10334 | LY1: TRX-10335 | LZ1: TRX-10336 | MA1: TRX-10337 | MB1: TRX-10338 | MC1: TRX-10339 | MD1: TRX-10340 | ME1: TRX-10341 | MF1: TRX-10342 | MG1: TRX-10343 | MH1: TRX-10344 | MI1: TRX-10345 | MJ1: TRX-10346 | MK1: TRX-10347 | ML1: TRX-10348 | MM1: TRX-10349 | MN1: TRX-10350 | MO1: TRX-10351 | MP1: TRX-10352 | MQ1: TRX-10353 | MR1: TRX-10354 | MS1: TRX-10355 | MT1: TRX-10356 | MU1: TRX-10357 | MV1: TRX-10358 | MW1: TRX-10359 | MX1: TRX-10360 | MY1: TRX-10361 | MZ1: TRX-10362 | NA1: TRX-10363 | NB1: TRX-10364 | NC1: TRX-10365 | ND1: TRX-10366 | NE1: TRX-10367 | NF1: TRX-10368 | NG1: TRX-10369 | NH1: TRX-10370 | NI1: TRX-10371 | NJ1: TRX-10372 | NK1: TRX-10373 | NL1: TRX-10374 | NM1: TRX-10375 | NN1: TRX-10376 | NO1: TRX-10377 | NP1: TRX-10378 | NQ1: TRX-10379 | NR1: TRX-10380 | NS1: TRX-10381 | NT1: TRX-10382 | NU1: TRX-10383 | NV1: TRX-10384 | NW1: TRX-10385 | NX1: TRX-10386 | NY1: TRX-10387 | NZ1: TRX-10388 | OA1: TRX-10389 | OB1: TRX-10390 | OC1: TRX-10391 | OD1: TRX-10392 | OE1: TRX-10393 | OF1: TRX-10394 | OG1: TRX-10395 | OH1: TRX-10396 | OI1: TRX-10397 | OJ1: TRX-10398 | OK1: TRX-10399 | OL1: TRX-10400 | OM1: TRX-10401 | ON1: TRX-10402 | OO1: TRX-10403 | OP1: TRX-10404 | OQ1: TRX-10405 | OR1: TRX-10406 | OS1: TRX-10407 | OT1: TRX-10408 | OU1: TRX-10409 | OV1: TRX-10410 | OW1: TRX-10411 | OX1: TRX-10412 | OY1: TRX-10413 | OZ1: TRX-10414 | PA1: TRX-10415 | PB1: TRX-10416 | PC1: TRX-10417 | PD1: TRX-10418 | PE1: TRX-10419 | PF1: TRX-10420 | PG1: TRX-10421 | PH1: TRX-10422 | PI1: TRX-10423 | PJ1: TRX-10424 | PK1: TRX-10425 | PL1: TRX-10426 | PM1: TRX-10427 | PN1: TRX-10428 | PO1: TRX-10429 | PP1: TRX-10430 | PQ1: TRX-10431 | PR1: TRX-10432 | PS1: TRX-10433 | PT1: TRX-10434 | PU1: TRX-10435 | PV1: TRX-10436 | PW1: TRX-10437 | PX1: TRX-10438 | PY1: TRX-10439 | PZ1: TRX-10440 | QA1: TRX-10441 | QB1: TRX-10442 | QC1: TRX-10443 | QD1: TRX-10444 | QE1: TRX-10445 | QF1: TRX-10446 | QG1: TRX-10447 | QH1: TRX-10448 | QI1: TRX-10449 | QJ1: TRX-10450 | QK1: TRX-10451 | QL1: TRX-10452 | QM1: TRX-10453 | QN1: TRX-10454 | QO1: TRX-10455 | QP1: TRX-10456 | QQ1: TRX-10457 | QR1: TRX-10458 | QS1: TRX-10459 | QT1: TRX-10460 | QU1: TRX-10461 | QV1: TRX-10462 | QW1: TRX-10463 | QX1: TRX-10464 | QY1: TRX-10465 | QZ1: TRX-10466 | RA1: TRX-10467 | RB1: TRX-10468 | RC1: TRX-10469 | RD1: TRX-10470 | RE1: TRX-10471 | RF1: TRX-10472 | RG1: TRX-10473 | RH1: TRX-10474 | RI1: TRX-10475 | RJ1: TRX-10476 | RK1: TRX-10477 | RL1: TRX-10478 | RM1: TRX-10479 | RN1: TRX-10480 | RO1: TRX-10481 | RP1: TRX-10482 | RQ1: TRX-10483 | RR1: TRX-10484 | RS1: TRX-10485 | RT1: TRX-10486 | RU1: TRX-10487 | RV1: TRX-10488 | RW1: TRX-10489 | RX1: TRX-10490 | RY1: TRX-10491 | RZ1: TRX-10492 | SA1: TRX-10493 | SB1: TRX-10494 | SC1: TRX-10495 | SD1: TRX-10496 | SE1: TRX-10497 | SF1: TRX-10498 | SG1: TRX-10499 | SH1: TRX-10500 | SI1: TRX-10501 | SJ1: TRX-10502 | SK1: TRX-10503 | SL1: TRX-10504 | SM1: TRX-10505 | SN1: TRX-10506 | SO1: TRX-10507 | SP1: TRX-10508 | SQ1: TRX-10509 | SR1: TRX-10510 | SS1: TRX-10511 | ST1: TRX-10512 | SU1: TRX-10513 | SV1: TRX-10514 | SW1: TRX-10515 | SX1: TRX-10516 | SY1: TRX-10517 | SZ1: TRX-10518 | TA1: TRX-10519 | TB1: TRX-10520 | TC1: TRX-10521 | TD1: TRX-10522 | TE1: TRX-10523 | TF1: TRX-10524 | TG1: TRX-10525 | TH1: TRX-10526 | TI1: TRX-10527 | TJ1: TRX-10528 | TK1: TRX-10529 | TL1: TRX-10530 | TM1: TRX-10531 | TN1: TRX-10532 | TO1: TRX-10533 | TP1: TRX-10534 | TQ1: TRX-10535 | TR1: TRX-10536 | TS1: TRX-10537 | TT1: TRX-10538 | TU1: TRX-10539 | TV1: TRX-10540 | TW1: TRX-10541 | TX1: TRX-10542 | TY1: TRX-10543 | TZ1: TRX-10544 | UA1: TRX-10545 | UB1: TRX-10546 | UC1: TRX-10547 | UD1: TRX-10548 | UE1: TRX-10549 | UF1: TRX-10550 | UG1: TRX-10551 | UH1: TRX-10552 | UI1: TRX-10553 | UJ1: TRX-10554 | UK1: TRX-10555 | UL1: TRX-10556 | UM1: TRX-10557 | UN1: TRX-10558 | UO1: TRX-10559 | UP1: TRX-10560 | UQ1: TRX-10561 | UR1: TRX-10562 | US1: TRX-10563 | UT1: TRX-10564 | UU1: TRX-10565 | UV1: TRX-10566 | UW1: TRX-10567 | UX1: TRX-10568 | UY1: TRX-10569 | UZ1: TRX-10570 | VA1: TRX-10571 | VB1: TRX-10572 | VC1: TRX-10573 | VD1: TRX-10574 | VE1: TRX-10575 | VF1: TRX-10576 | VG1: TRX-10577 | VH1: TRX-10578 | VI1: TRX-10579 | VJ1: TRX-10580 | VK1: TRX-10581 | VL1: TRX-10582 | VM1: TRX-10583 | VN1: TRX-10584 | VO1: TRX-10585 | VP1: TRX-10586 | VQ1: TRX-10587 | VR1: TRX-10588 | VS1: TRX-10589 | VT1: TRX-10590 | VU1: TRX-10591 | VV1: TRX-10592 | VW1: TRX-10593 | VX1: TRX-10594 | VY1: TRX-10595 | VZ1: TRX-10596 | WA1: TRX-10597 | WB1: TRX-10598 | WC1: TRX-10599 | WD1: TRX-10600 | WE1: TRX-10601 | WF1: TRX-10602 | WG1: TRX-10603 | WH1: TRX-10604 | WI1: TRX-10605 | WJ1: TRX-10606 | WK1: TRX-10607 | WL1: TRX-10608 | WM1: TRX-10609 | WN1: TRX-10610 | WO1: TRX-10611 | WP1: TRX-10612 | WQ1: TRX-10613 | WR1: TRX-10614 | WS1: TRX-10615 | WT1: TRX-10616 | WU1: TRX-10617 | WV1: TRX-10618 | WW1: TRX-10619 | WX1: TRX-10620 | WY1: TRX-10621 | WZ1: TRX-10622 | XA1: TRX-10623 | XB1: TRX-10624 | XC1: TRX-10625 | XD1: TRX-10626 | XE1: TRX-10627 | XF1: TRX-10628 | XG1: TRX-10629 | XH1: TRX-10630 | XI1: TRX-10631 | XJ1: TRX-10632 | XK1: TRX-10633 | XL1: TRX-10634 | XM1: TRX-10635 | XN1: TRX-10636 | XO1: TRX-10637 | XP1: TRX-10638 | XQ1: TRX-10639 | XR1: TRX-10640 | XS1: TRX-10641 | XT1: TRX-10642 | XU1: TRX-10643 | XV1: TRX-10644 | XW1: TRX-10645 | XX1: TRX-10646 | XY1: TRX-10647 | XZ1: TRX-10648 | YA1: TRX-10649 | YB1: TRX-10650 | YC1: TRX-10651 | YD1: TRX-10652 | YE1: TRX-10653 | YF1: TRX-10654 | YG1: TRX-10655 | YH1: TRX-10656 | YI1: TRX-10657 | YJ1: TRX-10658 | YK1: TRX-10659 | YL1: TRX-10660 | YM1: TRX-10661 | YN1: TRX-10662 | YO1: TRX-10663 | YP1: TRX-10664 | YQ1: TRX-10665 | YR1: TRX-10666 | YS1: TRX-10667 | YT1: TRX-10668 | YU1: TRX-10669 | YV1: TRX-10670 | YW1: TRX-10671 | YX1: TRX-10672 | YY1: TRX-10673 | YZ1: TRX-10674 | ZA1: TRX-10675 | ZB1: TRX-10676 | ZC1: TRX-10677 | ZD1: TRX-10678 | ZE1: TRX-10679 | ZF1: TRX-10680 | ZG1: TRX-10681 | ZH1: TRX-10682 | ZI1: TRX-10683 | ZJ1: TRX-10684 | ZK1: TRX-10685 | ZL1: TRX-10686 | ZM1: TRX-10687 | ZN1: TRX-10688 | ZO1: TRX-10689 | ZP1: TRX-10690 | ZQ1: TRX-10691 | ZR1: TRX-10692 | ZS1: TRX-10693 | ZT1: TRX-10694 | ZU1: TRX-10695 | ZV1: TRX-10696 | ZW1: TRX-10697 | ZX1: TRX-10698 | ZY1: TRX-10699 | ZZ1: TRX-10700 | AAA1: TRX-10701 | AAB1: TRX-10702 | AAC1: TRX-10703 | AAD1: TRX-10704 | AAE1: TRX-10705 | AAF1: TRX-10706 | AAG1: TRX-10707 | AAH1: TRX-10708 | AAI1: TRX-10709 | AAJ1: TRX-10710 | AAK1: TRX-10711 | AAL1: TRX-10712 | AAM1: TRX-10713 | AAN1: TRX-10714 | AAO1: TRX-10715 | AAP1: TRX-10716 | AAQ1: TRX-10717 | AAR1: TRX-10718 | AAS1: TRX-10719 | AAT1: TRX-10720 | AAU1: TRX-10721 | AAV1: TRX-10722 | AAW1: TRX-10723 | AAX1: TRX-10724 | AAY1: TRX-10725 | AAZ1: TRX-10726 | ABA1: TRX-10727 | ABB1: TRX-10728 | ABC1: TRX-10729 | ABD1: TRX-10730 | ABE1: TRX-10731 | ABF1: TRX-10732 | ABG1: TRX-10733 | ABH1: TRX-10734 | ABI1: TRX-10735 | ABJ1: TRX-10736 | ABK1: TRX-10737 | ABL1: TRX-10738 | ABM1: TRX-10739 | ABN1: TRX-10740 | ABO1: TRX-10741 | ABP1: TRX-10742 | ABQ1: TRX-10743 | ABR1: TRX-10744 | ABS1: TRX-10745 | ABT1: TRX-10746 | ABU1: TRX-10747 | ABV1: TRX-10748 | ABW1: TRX-10749 | ABX1: TRX-10750 | ABY1: TRX-10751 | ABZ1: TRX-10752 | ACA1: TRX-10753 | ACB1: TRX-10754 | ACC1: TRX-10755 | ACD1: TRX-10756 | ACE1: TRX-10757 | ACF1: TRX-10758 | ACG1: TRX-10759 | ACH1: TRX-10760 | ACI1: TRX-10761 | ACJ1: TRX-10762 | ACK1: TRX-10763 | ACL1: TRX-10764 | ACM1: TRX-10765 | ACN1: TRX-10766 | ACO1: TRX-10767 | ACP1: TRX-10768 | ACQ1: TRX-10769 | ACR1: TRX-10770 | ACS1: TRX-10771 | ACT1: TRX-10772 | ACU1: TRX-10773 | ACV1: TRX-10774 | ACW1: TRX-10775 | ACX1: TRX-10776 | ACY1: TRX-10777 | ACZ1: TRX-10778 | ADA1: TRX-10779 | ADB1: TRX-10780 | ADC1: TRX-10781 | ADD1: TRX-10782 | ADE1: TRX-10783 | ADF1: TRX-10784 | ADG1: TRX-10785 | ADH1: TRX-10786 | ADI1: TRX-10787 | ADJ1: TRX-10788 | ADK1: TRX-10789 | ADL1: TRX-10790 | ADM1: TRX-10791 | ADN1: TRX-10792 | ADO1: TRX-10793 | ADP1: TRX-10794 | ADQ1: TRX-10795 | ADR1: TRX-10796 | ADS1: TRX-10797 | ADT1: TRX-10798 | ADU1: TRX-10799 | ADV1: TRX-10800 | ADW1: TRX-10801 | ADX1: TRX-10802 | ADY1: TRX-10803 | ADZ1: TRX-10804 | AEA1: TRX-10805 | AEB1: TRX-10806 | AEC1: TRX-10807 | AED1: TRX-10808 | AEE1: TRX-10809 | AEF1: TRX-10810 | AEG1: TRX-10811 | AEH1: TRX-10812 | AEI1: TRX-10813 | AEJ1: TRX-10814 | AEK1: TRX-10815 | AEL1: TRX-10816 | AEM1: TRX-10817 | AEN1: TRX-10818 | AEO1: TRX-10819 | AEP1: TRX-10820 | AEQ1: TRX-10821 | AER1: TRX-10822 | AES1: TRX-10823 | AET1: TRX-10824 | AEU1: TRX-10825 | AEV1: TRX-10826 | AEW1: TRX-10827 | AEX1: TRX-10828 | AEY1: TRX-10829 | AEZ1: TRX-10830 | AFA1: TRX-10831 | AFB1: TRX-10832 | AFC1: TRX-10833 | AFD1: TRX-10834 | AFE1: TRX-10835 | AFF1: TRX-10836 | AFG1: TRX-10837 | AFH1: TRX-10838 | AFI1: TRX-10839 | AFJ1: TRX-10840 | AFK1: TRX-10841 | AFL1: TRX-10842 | AFM1: TRX-10843 | AFN1: TRX-10844 | AFO1: TRX-10845 | AFP1: TRX-10846 | AFQ1: TRX-10847 | AFR1: TRX-10848 | AFS1: TRX-10849 | AFT1: TRX-10850 | AFU1: TRX-10851 | AFV1: TRX-10852 | AFW1: TRX-10853 | AFX1: TRX-10854 | AFY1: TRX-10855 | AFZ1: TRX-10856 | AGA1: TRX-10857 | AGB1: TRX-10858 | AGC1: TRX-10859 | AGD1: TRX-10860 | AGE1: TRX-10861 | AGF1: TRX-10862 | AGG1: TRX-10863 | AGH1: TRX-10864 | AGI1: TRX-10865 | AGJ1: TRX-10866 | AGK1: TRX-10867 | AGL1: TRX-10868 | AGM1: TRX-10869 | AGN1: TRX-10870 | AGO1: TRX-10871 | AGP1: TRX-10872 | AGQ1: TRX-10873 | AGR1: TRX-10874 | AGS1: TRX-10875 | AGT1: TRX-10876 | AGU1: TRX-10877 | AGV1: TRX-10878 | AGW1: TRX-10879 | AGX1: TRX-10880 | AGY1: TRX-10881 | AGZ1: TRX-10882 | AHA1: TRX-10883 | AHB1: TRX-10884 | AHC1: TRX-10885 | AHD1: TRX-10886 | AHE1: TRX-10887 | AHF1: TRX-10888 | AHG1: TRX-10889 | AHH1: TRX-10890 | AHI1: TRX-10891 | AHJ1: TRX-10892 | AHK1: TRX-10893 | AHL1: TRX-10894 | AHM1: TRX-10895 | AHN1: TRX-10896 | AHO1: TRX-10897 | AHP1: TRX-10898 | AHQ1: TRX-10899 | AHR1: TRX-10900 | AHS1: TRX-10901 | AHT1: TRX-10902 | AHU1: TRX-10903 | AHV1: TRX-10904 | AHW1: TRX-10905 | AHX1: TRX-10906 | AHY1: TRX-10907 | AHZ1: TRX-10908 | AIA1: TRX-10909 | AIB1: TRX-10910 | AIC1: TRX-10911 | AID1: TRX-10912 | AIE1: TRX-10913 | AIF1: TRX-10914 | AIG1: TRX-10915 | AIH1: TRX-10916 | AII1: TRX-10917 | AIJ1: TRX-10918 | AIK1: TRX-10919 | AIL1: TRX-10920 | AIM1: TRX-10921 | AIN1: TRX-10922 | AIO1: TRX-10923 | AIP1: TRX-10924 | AIQ1: TRX-10925 | AIR1: TRX-10926 | AIS1: TRX-10927 | AIT1: TRX-10928 | AIU1: TRX-10929 | AIV1: TRX-10930 | AIW1: TRX-10931 | AIX1: TRX-10932 | AIY1: TRX-10933 | AIZ1: TRX-10934 | AJA1: TRX-10935 | AJB1: TRX-10936 | AJC1: TRX-10937 | AJD1: TRX-10938 | AJE1: TRX-10939 | AJF1: TRX-10940 | AJG1: TRX-10941 | AJH1: TRX-10942 | AJI1: TRX-10943 | AJJ1: TRX-10944 | AJK1: TRX-10945 | AJL1: TRX-10946 | AJM1: TRX-10947 | AJN1: TRX-10948 | AJO1: TRX-10949 | AJP1: TRX-10950 | AJQ1: TRX-10951 | AJR1: TRX-10952 | AJS1: TRX-10953 | AJT1: TRX-10954 | AJU1: TRX-10955 | AJV1: TRX-10956 | AJW1: TRX-10957 | AJX1: TRX-10958 | AJY1: TRX-10959 | AJZ1: TRX-10960 | AKA1: TRX-10961 | AKB1: TRX-10962 | AKC1: TRX-10963 | AKD1: TRX-10964 | AKE1: TRX-10965 | AKF1: TRX-10966 | AKG1: TRX-10967 | AKH1: TRX-10968 | AKI1: TRX-10969 | AKJ1: TRX-10970 | AKK1: TRX-10971 | AKL1: TRX-10972 | AKM1: TRX-10973 | AKN1: TRX-10974 | AKO1: TRX-10975 | AKP1: TRX-10976 | AKQ1: TRX-10977 | AKR1: TRX-10978 | AKS1: TRX-10979 | AKT1: TRX-10980 | AKU1: TRX-10981 | AKV1: TRX-10982 | AKW1: TRX-10983 | AKX1: TRX-10984 | AKY1: TRX-10985 | AKZ1: TRX-10986 | ALA1: TRX-10987 | ALB1: TRX-10988 | ALC1: TRX-10989 | ALD1: TRX-10990 | ALE1: TRX-10991 | ALF1: TRX-10992 | ALG1: TRX-10993 | ALH1: TRX-10994 | ALI1: TRX-10995 | ALJ1: TRX-10996 | ALK1: TRX-10997 | ALL1: TRX-10998 | ALM1: TRX-10999
A2: Date | B2: 46088 | C2: 46007 | D2: 45886 | E2: 46015 | F2: 45980 | G2: 46170 | H2: 46132 | I2: 46226 | J2: 46066 | K2: 46230 | L2: 45945 | M2: 46203 | N2: 46076 | O2: 45927 | P2: 46137 | Q2: 46208 | R2: 46029 | S2: 45988 | T2: 46166 | U2: 46012 | V2: 46174 | W2: 46172 | X2: 46175 | Y2: 46015 | Z2: 46124 | AA2: 46133 | AB2: 46209 | AC2: 45972 | AD2: 46204 | AE2: 46178 | AF2: 46012 | AG2: 46152 | AH2: 46105 | AI2: 46219 | AJ2: 45890 | AK2: 45974 | AL2: 45899 | AM2: 46221 | AN2: 45890 | AO2: 46134 | AP2: 46126 | AQ2: 46054 | AR2: 46025 | AS2: 46011 | AT2: 46101 | AU2: 46081 | AV2: 46054 | AW2: 46024 | AX2: 46000 | AY2: 46155 | AZ2: 45990 | BA2: 45914 | BB2: 46086 | BC2: 46149 | BD2: 45904 | BE2: 45942 | BF2: 45882 | BG2: 45871 | BH2: 46221 | BI2: 45941 | BJ2: 46214 | BK2: 46084 | BL2: 46225 | BM2: 45947 | BN2: 46042 | BO2: 46160 | BP2: 46096 | BQ2: 46000 | BR2: 46107 | BS2: 46089 | BT2: 46185 | BU2: 45922 | BV2: 46014 | BW2: 46090 | BX2: 45988 | BY2: 46079 | BZ2: 46142 | CA2: 45879 | CB2: 46147 | CC2: 46216 | CD2: 46153 | CE2: 46179 | CF2: 46224 | CG2: 46131 | CH2: 46072 | CI2: 46120 | CJ2: 46127 | CK2: 45953 | CL2: 46154 | CM2: 45958 | CN2: 45956 | CO2: 46148 | CP2: 46031 | CQ2: 46032 | CR2: 45919 | CS2: 46031 | CT2: 45971 | CU2: 46038 | CV2: 46056 | CW2: 45984 | CX2: 46136 | CY2: 46228 | CZ2: 46030 | DA2: 46049 | DB2: 46191 | DC2: 46005 | DD2: 45979 | DE2: 46067 | DF2: 45948 | DG2: 45971 | DH2: 45910 | DI2: 46133 | DJ2: 45995 | DK2: 45966 | DL2: 45950 | DM2: 45941 | DN2: 46192 | DO2: 45970 | DP2: 45994 | DQ2: 46002 | DR2: 46107 | DS2: 46012 | DT2: 46194 | DU2: 46208 | DV2: 45894 | DW2: 45911 | DX2: 46164 | DY2: 46042 | DZ2: 46149 | EA2: 45915 | EB2: 46123 | EC2: 45894 | ED2: 45917 | EE2: 45965 | EF2: 46064 | EG2: 45888 | EH2: 45903 | EI2: 45930 | EJ2: 46117 | EK2: 45944 | EL2: 46225 | EM2: 46055 | EN2: 46161 | EO2: 46064 | EP2: 46014 | EQ2: 46131 | ER2: 46132 | ES2: 45953 | ET2: 46076 | EU2: 46209 | EV2: 46040 | EW2: 46165 | EX2: 45929 | EY2: 45920 | EZ2: 46190 | FA2: 46043 | FB2: 45915 | FC2: 46031 | FD2: 46007 | FE2: 45957 | FF2: 45929 | FG2: 46186 | FH2: 46049 | FI2: 45887 | FJ2: 45980 | FK2: 46096 | FL2: 46025 | FM2: 46064 | FN2: 46015 | FO2: 45978 | FP2: 46165 | FQ2: 46231 | FR2: 45959 | FS2: 45918 | FT2: 45992 | FU2: 45902 | FV2: 46155 | FW2: 45957 | FX2: 46190 | FY2: 46065 | FZ2: 45956 | GA2: 45891 | GB2: 46165 | GC2: 46128 | GD2: 45950 | GE2: 46234 | GF2: 46219 | GG2: 46153 | GH2: 46197 | GI2: 45954 | GJ2: 45876 | GK2: 45975 | GL2: 46199 | GM2: 45953 | GN2: 46049 | GO2: 45948 | GP2: 46032 | GQ2: 46009 | GR2: 46052 | GS2: 46122 | GT2: 45961 | GU2: 46190 | GV2: 46129 | GW2: 46067 | GX2: 46135 | GY2: 45933 | GZ2: 45988 | HA2: 45895 | HB2: 46046 | HC2: 45946 | HD2: 45975 | HE2: 45998 | HF2: 46226 | HG2: 45947 | HH2: 46101 | HI2: 46084 | HJ2: 46156 | HK2: 46091 | HL2: 45998 | HM2: 46182 | HN2: 46025 | HO2: 45881 | HP2: 46214 | HQ2: 45955 | HR2: 46207 | HS2: 46109 | HT2: 46153 | HU2: 46090 | HV2: 46041 | HW2: 46101 | HX2: 46142 | HY2: 45913 | HZ2: 46224 | IA2: 45994 | IB2: 46168 | IC2: 46125 | ID2: 46042 | IE2: 46021 | IF2: 46101 | IG2: 46116 | IH2: 46211 | II2: 45925 | IJ2: 46063 | IK2: 46161 | IL2: 46188 | IM2: 46011 | IN2: 46182 | IO2: 45936 | IP2: 46090 | IQ2: 45898 | IR2: 46118 | IS2: 46192 | IT2: 46167 | IU2: 45931 | IV2: 45966 | IW2: 46131 | IX2: 46172 | IY2: 46122 | IZ2: 46081 | JA2: 46200 | JB2: 46112 | JC2: 46041 | JD2: 46012 | JE2: 45937 | JF2: 45898 | JG2: 45896 | JH2: 46026 | JI2: 45888 | JJ2: 46028 | JK2: 45980 | JL2: 45908 | JM2: 46150 | JN2: 45988 | JO2: 46041 | JP2: 46108 | JQ2: 46128 | JR2: 46111 | JS2: 45922 | JT2: 46019 | JU2: 45938 | JV2: 45949 | JW2: 45932 | JX2: 46115 | JY2: 45900 | JZ2: 46228 | KA2: 46097 | KB2: 46098 | KC2: 45944 | KD2: 46227 | KE2: 45927 | KF2: 46048 | KG2: 46063 | KH2: 46160 | KI2: 46107 | KJ2: 45957 | KK2: 45901 | KL2: 46000 | KM2: 45963 | KN2: 46001 | KO2: 46088 | KP2: 46215 | KQ2: 45890 | KR2: 46031 | KS2: 45983 | KT2: 46130 | KU2: 45876 | KV2: 45946 | KW2: 46024 | KX2: 46119 | KY2: 46226 | KZ2: 46230 | LA2: 46007 | LB2: 45963 | LC2: 46090 | LD2: 45950 | LE2: 46063 | LF2: 46026 | LG2: 45930 | LH2: 46151 | LI2: 45925 | LJ2: 46045 | LK2: 45970 | LL2: 46140 | LM2: 46135 | LN2: 46141 | LO2: 46166 | LP2: 46061 | LQ2: 46161 | LR2: 46089 | LS2: 46050 | LT2: 46124 | LU2: 45901 | LV2: 45917 | LW2: 46045 | LX2: 45905 | LY2: 46106 | LZ2: 46177 | MA2: 46140 | MB2: 45920 | MC2: 46212 | MD2: 46064 | ME2: 45913 | MF2: 45935 | MG2: 46206 | MH2: 45882 | MI2: 45999 | MJ2: 46010 | MK2: 45887 | ML2: 46203 | MM2: 46019 | MN2: 45931 | MO2: 45996 | MP2: 46139 | MQ2: 46144 | MR2: 46173 | MS2: 45914 | MT2: 46076 | MU2: 45979 | MV2: 45938 | MW2: 45981 | MX2: 45903 | MY2: 46145 | MZ2: 46109 | NA2: 46170 | NB2: 46068 | NC2: 46083 | ND2: 46161 | NE2: 45915 | NF2: 45954 | NG2: 46185 | NH2: 46055 | NI2: 46061 | NJ2: 45982 | NK2: 46121 | NL2: 45955 | NM2: 46110 | NN2: 46034 | NO2: 46025 | NP2: 46086 | NQ2: 46206 | NR2: 46082 | NS2: 46077 | NT2: 45929 | NU2: 46064 | NV2: 46200 | NW2: 46023 | NX2: 45879 | NY2: 46167 | NZ2: 46029 | OA2: 46138 | OB2: 46156 | OC2: 45989 | OD2: 45870 | OE2: 46144 | OF2: 46231 | OG2: 45958 | OH2: 46111 | OI2: 46219 | OJ2: 45913 | OK2: 46092 | OL2: 46163 | OM2: 46038 | ON2: 45919 | OO2: 46221 | OP2: 46130 | OQ2: 46107 | OR2: 46056 | OS2: 46161 | OT2: 46196 | OU2: 46092 | OV2: 46047 | OW2: 46165 | OX2: 46013 | OY2: 46116 | OZ2: 46152 | PA2: 45905 | PB2: 45907 | PC2: 45958 | PD2: 45894 | PE2: 45957 | PF2: 45999 | PG2: 45955 | PH2: 46218 | PI2: 46065 | PJ2: 45988 | PK2: 45876 | PL2: 46151 | PM2: 46133 | PN2: 46056 | PO2: 46081 | PP2: 46116 | PQ2: 45884 | PR2: 46109 | PS2: 46128 | PT2: 46052 | PU2: 46224 | PV2: 46008 | PW2: 46091 | PX2: 46144 | PY2: 46056 | PZ2: 45944 | QA2: 46231 | QB2: 46079 | QC2: 45944 | QD2: 46016 | QE2: 46126 | QF2: 46232 | QG2: 46225 | QH2: 46208 | QI2: 45983 | QJ2: 46024 | QK2: 46216 | QL2: 45983 | QM2: 46111 | QN2: 46003 | QO2: 46169 | QP2: 45957 | QQ2: 45933 | QR2: 46080 | QS2: 46086 | QT2: 45918 | QU2: 46180 | QV2: 46057 | QW2: 45943 | QX2: 45875 | QY2: 46165 | QZ2: 46206 | RA2: 46225 | RB2: 45896 | RC2: 45931 | RD2: 46194 | RE2: 46005 | RF2: 45889 | RG2: 46005 | RH2: 46052 | RI2: 46163 | RJ2: 46009 | RK2: 45923 | RL2: 46192 | RM2: 46153 | RN2: 45910 | RO2: 45902 | RP2: 45993 | RQ2: 45937 | RR2: 46118 | RS2: 46209 | RT2: 46183 | RU2: 45872 | RV2: 46185 | RW2: 46136 | RX2: 46110 | RY2: 46230 | RZ2: 46205 | SA2: 46210 | SB2: 46039 | SC2: 45951 | SD2: 45932 | SE2: 45953 | SF2: 46042 | SG2: 46234 | SH2: 46162 | SI2: 45911 | SJ2: 45960 | SK2: 45910 | SL2: 45925 | SM2: 46215 | SN2: 46084 | SO2: 46235 | SP2: 45939 | SQ2: 46024 | SR2: 46000 | SS2: 46139 | ST2: 46046 | SU2: 46184 | SV2: 46212 | SW2: 46053 | SX2: 46007 | SY2: 46062 | SZ2: 46130 | TA2: 45998 | TB2: 46174 | TC2: 46081 | TD2: 46092 | TE2: 46211 | TF2: 46078 | TG2: 46097 | TH2: 45912 | TI2: 46153 | TJ2: 46134 | TK2: 46009 | TL2: 46081 | TM2: 46230 | TN2: 46155 | TO2: 46069 | TP2: 46007 | TQ2: 46209 | TR2: 46107 | TS2: 46063 | TT2: 46090 | TU2: 45905 | TV2: 46019 | TW2: 45929 | TX2: 45905 | TY2: 45973 | TZ2: 46183 | UA2: 45921 | UB2: 45963 | UC2: 46095 | UD2: 46016 | UE2: 46233 | UF2: 45960 | UG2: 45875 | UH2: 45926 | UI2: 45879 | UJ2: 45890 | UK2: 46194 | UL2: 46012 | UM2: 46094 | UN2: 45979 | UO2: 46194 | UP2: 45986 | UQ2: 45972 | UR2: 45978 | US2: 45919 | UT2: 46226 | UU2: 46147 | UV2: 45911 | UW2: 46214 | UX2: 46203 | UY2: 46069 | UZ2: 46022 | VA2: 45971 | VB2: 46132 | VC2: 46195 | VD2: 45929 | VE2: 46107 | VF2: 45943 | VG2: 46205 | VH2: 46177 | VI2: 45998 | VJ2: 46038 | VK2: 46118 | VL2: 45874 | VM2: 46096 | VN2: 46227 | VO2: 46164 | VP2: 46121 | VQ2: 46120 | VR2: 45871 | VS2: 45932 | VT2: 46105 | VU2: 46120 | VV2: 45876 | VW2: 46058 | VX2: 46022 | VY2: 46196 | VZ2: 45924 | WA2: 45871 | WB2: 46041 | WC2: 45912 | WD2: 45896 | WE2: 46187 | WF2: 46098 | WG2: 45879 | WH2: 46060 | WI2: 46206 | WJ2: 46113 | WK2: 45870 | WL2: 46099 | WM2: 46013 | WN2: 46197 | WO2: 46196 | WP2: 46103 | WQ2: 46221 | WR2: 46167 | WS2: 46193 | WT2: 45976 | WU2: 46091 | WV2: 46130 | WW2: 46225 | WX2: 46151 | WY2: 46013 | WZ2: 46109 | XA2: 46113 | XB2: 45904 | XC2: 46029 | XD2: 46186 | XE2: 46185 | XF2: 45984 | XG2: 45994 | XH2: 46082 | XI2: 45919 | XJ2: 46021 | XK2: 46026 | XL2: 46156 | XM2: 46118 | XN2: 46136 | XO2: 46112 | XP2: 45953 | XQ2: 45924 | XR2: 45901 | XS2: 45964 | XT2: 45926 | XU2: 46220 | XV2: 46184 | XW2: 46067 | XX2: 45879 | XY2: 46121 | XZ2: 46075 | YA2: 46162 | YB2: 45962 | YC2: 45955 | YD2: 46187 | YE2: 45999 | YF2: 46164 | YG2: 46020 | YH2: 45936 | YI2: 45930 | YJ2: 46101 | YK2: 46185 | YL2: 46107 | YM2: 45920 | YN2: 45985 | YO2: 45908 | YP2: 46137 | YQ2: 45930 | YR2: 45921 | YS2: 45980 | YT2: 46067 | YU2: 45959 | YV2: 46162 | YW2: 46118 | YX2: 46119 | YY2: 46176 | YZ2: 45900 | ZA2: 46157 | ZB2: 45888 | ZC2: 46043 | ZD2: 46004 | ZE2: 46138 | ZF2: 46191 | ZG2: 45922 | ZH2: 46034 | ZI2: 45915 | ZJ2: 45955 | ZK2: 46043 | ZL2: 46221 | ZM2: 46208 | ZN2: 46140 | ZO2: 46220 | ZP2: 46077 | ZQ2: 46061 | ZR2: 46017 | ZS2: 46008 | ZT2: 46219 | ZU2: 46014 | ZV2: 46142 | ZW2: 45895 | ZX2: 45905 | ZY2: 45870 | ZZ2: 45986 | AAA2: 46205 | AAB2: 46161 | AAC2: 46216 | AAD2: 45887 | AAE2: 46188 | AAF2: 46198 | AAG2: 46114 | AAH2: 46099 | AAI2: 46118 | AAJ2: 46203 | AAK2: 46208 | AAL2: 46032 | AAM2: 46007 | AAN2: 46167 | AAO2: 45894 | AAP2: 46126 | AAQ2: 46211 | AAR2: 45902 | AAS2: 46073 | AAT2: 46146 | AAU2: 45990 | AAV2: 46215 | AAW2: 45981 | AAX2: 45925 | AAY2: 46088 | AAZ2: 46183 | ABA2: 46030 | ABB2: 45925 | ABC2: 45882 | ABD2: 45934 | ABE2: 45944 | ABF2: 45913 | ABG2: 46020 | ABH2: 46160 | ABI2: 45973 | ABJ2: 46025 | ABK2: 46172 | ABL2: 45946 | ABM2: 46034 | ABN2: 45922 | ABO2: 45933 | ABP2: 45979 | ABQ2: 46171 | ABR2: 45952 | ABS2: 46195 | ABT2: 45887 | ABU2: 46164 | ABV2: 46077 | ABW2: 46085 | ABX2: 46059 | ABY2: 46018 | ABZ2: 46185 | ACA2: 46231 | ACB2: 46211 | ACC2: 46208 | ACD2: 46180 | ACE2: 46217 | ACF2: 45976 | ACG2: 46209 | ACH2: 46164 | ACI2: 46121 | ACJ2: 45900 | ACK2: 45966 | ACL2: 45985 | ACM2: 45956 | ACN2: 46229 | ACO2: 46134 | ACP2: 46018 | ACQ2: 45999 | ACR2: 46035 | ACS2: 46181 | ACT2: 45892 | ACU2: 46099 | ACV2: 45973 | ACW2: 46181 | ACX2: 46219 | ACY2: 45910 | ACZ2: 45910 | ADA2: 46178 | ADB2: 46041 | ADC2: 46126 | ADD2: 46050 | ADE2: 46197 | ADF2: 45969 | ADG2: 45937 | ADH2: 46123 | ADI2: 46130 | ADJ2: 46186 | ADK2: 46123 | ADL2: 45912 | ADM2: 46064 | ADN2: 46149 | ADO2: 46061 | ADP2: 45978 | ADQ2: 46102 | ADR2: 45920 | ADS2: 46144 | ADT2: 46059 | ADU2: 46068 | ADV2: 45943 | ADW2: 45966 | ADX2: 46182 | ADY2: 45899 | ADZ2: 46173 | AEA2: 46058 | AEB2: 46215 | AEC2: 45972 | AED2: 45896 | AEE2: 46183 | AEF2: 46007 | AEG2: 46054 | AEH2: 45992 | AEI2: 45989 | AEJ2: 45928 | AEK2: 45896 | AEL2: 46007 | AEM2: 46068 | AEN2: 45926 | AEO2: 46068 | AEP2: 46073 | AEQ2: 46103 | AER2: 45905 | AES2: 45977 | AET2: 45968 | AEU2: 45947 | AEV2: 45920 | AEW2: 45870 | AEX2: 46165 | AEY2: 46211 | AEZ2: 45883 | AFA2: 45974 | AFB2: 46033 | AFC2: 46085 | AFD2: 45977 | AFE2: 46137 | AFF2: 45907 | AFG2: 46177 | AFH2: 46075 | AFI2: 46210 | AFJ2: 46037 | AFK2: 45994 | AFL2: 45959 | AFM2: 45965 | AFN2: 46006 | AFO2: 45961 | AFP2: 45888 | AFQ2: 46043 | AFR2: 46221 | AFS2: 45963 | AFT2: 46100 | AFU2: 46087 | AFV2: 45982 | AFW2: 46178 | AFX2: 46141 | AFY2: 46209 | AFZ2: 46006 | AGA2: 46186 | AGB2: 45909 | AGC2: 46093 | AGD2: 46030 | AGE2: 46083 | AGF2: 46135 | AGG2: 46135 | AGH2: 45928 | AGI2: 46120 | AGJ2: 46156 | AGK2: 46042 | AGL2: 46136 | AGM2: 46089 | AGN2: 46199 | AGO2: 46038 | AGP2: 46185 | AGQ2: 46012 | AGR2: 45976 | AGS2: 45895 | AGT2: 46099 | AGU2: 46131 | AGV2: 45904 | AGW2: 46088 | AGX2: 45920 | AGY2: 46197 | AGZ2: 45995 | AHA2: 46081 | AHB2: 46197 | AHC2: 45969 | AHD2: 45991 | AHE2: 45950 | AHF2: 46130 | AHG2: 46176 | AHH2: 46094 | AHI2: 46129 | AHJ2: 46093 | AHK2: 46067 | AHL2: 46131 | AHM2: 45942 | AHN2: 46098 | AHO2: 45875 | AHP2: 45874 | AHQ2: 45921 | AHR2: 46118 | AHS2: 46212 | AHT2: 45992 | AHU2: 46011 | AHV2: 46190 | AHW2: 46105 | AHX2: 45914 | AHY2: 45872 | AHZ2: 45917 | AIA2: 45989 | AIB2: 46119 | AIC2: 46005 | AID2: 46113 | AIE2: 45872 | AIF2: 46235 | AIG2: 46129 | AIH2: 45886 | AII2: 45871 | AIJ2: 45957 | AIK2: 46005 | AIL2: 46229 | AIM2: 46087 | AIN2: 46224 | AIO2: 46164 | AIP2: 46053 | AIQ2: 46017 | AIR2: 46235 | AIS2: 45891 | AIT2: 45915 | AIU2: 45940 | AIV2: 46138 | AIW2: 46185 | AIX2: 45914 | AIY2: 45992 | AIZ2: 46002 | AJA2: 46065 | AJB2: 46216 | AJC2: 46111 | AJD2: 45903 | AJE2: 46212 | AJF2: 46208 | AJG2: 45939 | AJH2: 46081 | AJI2: 46191 | AJJ2: 46203 | AJK2: 45920 | AJL2: 46148 | AJM2: 46163 | AJN2: 46122 | AJO2: 46065 | AJP2: 45896 | AJQ2: 46001 | AJR2: 46231 | AJS2: 46206 | AJT2: 46156 | AJU2: 45895 | AJV2: 45901 | AJW2: 45887 | AJX2: 46059 | AJY2: 46026 | AJZ2: 45922 | AKA2: 46121 | AKB2: 46089 | AKC2: 46203 | AKD2: 46064 | AKE2: 45876 | AKF2: 46076 | AKG2: 46138 | AKH2: 45889 | AKI2: 46112 | AKJ2: 45913 | AKK2: 46096 | AKL2: 46223 | AKM2: 46228 | AKN2: 46147 | AKO2: 46105 | AKP2: 46219 | AKQ2: 46003 | AKR2: 46092 | AKS2: 45973 | AKT2: 45957 | AKU2: 46086 | AKV2: 45968 | AKW2: 46055 | AKX2: 46235 | AKY2: 46187 | AKZ2: 45926 | ALA2: 46097 | ALB2: 46058 | ALC2: 45970 | ALD2: 45930 | ALE2: 46049 | ALF2: 46193 | ALG2: 46139 | ALH2: 46199 | ALI2: 46115 | ALJ2: 46064 | ALK2: 46157 | ALL2: 46226 | ALM2: 46151
A3: Sales Rep | B3: Jamie | C3: Morgan | D3: Casey | E3: Jamie | F3: Taylor | G3: Drew | H3: Casey | I3: Casey | J3: Jamie | K3: Jordan | L3: Taylor | M3: Jamie | N3: Taylor | O3: Taylor | P3: Drew | Q3: Casey | R3: Morgan | S3: Drew | T3: Drew | U3: Taylor | V3: Sam | W3: Casey | X3: Jordan | Y3: Drew | Z3: Morgan | AA3: Sam | AB3: Sam | AC3: Jordan | AD3: Drew | AE3: Morgan | AF3: Casey | AG3: Alex | AH3: Morgan | AI3: Jordan | AJ3: Sam | AK3: Casey | AL3: Morgan | AM3: Alex | AN3: Alex | AO3: Taylor | AP3: Taylor | AQ3: Jamie | AR3: Jordan | AS3: Drew | AT3: Morgan | AU3: Morgan | AV3: Drew | AW3: Jamie | AX3: Sam | AY3: Sam | AZ3: Jamie | BA3: Sam | BB3: Taylor | BC3: Morgan | BD3: Jamie | BE3: Morgan | BF3: Drew | BG3: Alex | BH3: Taylor | BI3: Casey | BJ3: Taylor | BK3: Jamie | BL3: Casey | BM3: Alex | BN3: Jamie | BO3: Jordan | BP3: Morgan | BQ3: Alex | BR3: Morgan | BS3: Sam | BT3: Jordan | BU3: Jordan | BV3: Alex | BW3: Jordan | BX3: Casey | BY3: Jordan | BZ3: Morgan | CA3: Morgan | CB3: Jamie | CC3: Morgan | CD3: Jamie | CE3: Morgan | CF3: Casey | CG3: Drew | CH3: Jamie | CI3: Taylor | CJ3: Sam | CK3: Alex | CL3: Morgan | CM3: Jordan | CN3: Drew | CO3: Morgan | CP3: Jordan | CQ3: Sam | CR3: Sam | CS3: Sam | CT3: Jordan | CU3: Morgan | CV3: Sam | CW3: Casey | CX3: Jamie | CY3: Jordan | CZ3: Jordan | DA3: Morgan | DB3: Jordan | DC3: Jordan | DD3: Sam | DE3: Morgan | DF3: Sam | DG3: Jamie | DH3: Drew | DI3: Jamie | DJ3: Drew | DK3: Sam | DL3: Jamie | DM3: Morgan | DN3: Alex | DO3: Sam | DP3: Drew | DQ3: Casey | DR3: Drew | DS3: Casey | DT3: Jordan | DU3: Jamie | DV3: Casey | DW3: Drew | DX3: Jordan | DY3: Alex | DZ3: Morgan | EA3: Morgan | EB3: Morgan | EC3: Casey | ED3: Alex | EE3: Casey | EF3: Jamie | EG3: Casey | EH3: Alex | EI3: Alex | EJ3: Jamie | EK3: Alex | EL3: Drew | EM3: Alex | EN3: Morgan | EO3: Drew | EP3: Drew | EQ3: Jamie | ER3: Taylor | ES3: Taylor | ET3: Alex | EU3: Drew | EV3: Taylor | EW3: Taylor | EX3: Alex | EY3: Taylor | EZ3: Casey | FA3: Jordan | FB3: Jamie | FC3: Jordan | FD3: Alex | FE3: Morgan | FF3: Jamie | FG3: Alex | FH3: Drew | FI3: Morgan | FJ3: Jordan | FK3: Alex | FL3: Drew | FM3: Jamie | FN3: Jamie | FO3: Sam | FP3: Drew | FQ3: Casey | FR3: Taylor | FS3: Morgan | FT3: Drew | FU3: Sam | FV3: Taylor | FW3: Taylor | FX3: Alex | FY3: Taylor | FZ3: Casey | GA3: Jamie | GB3: Sam | GC3: Taylor | GD3: Alex | GE3: Casey | GF3: Jordan | GG3: Jamie | GH3: Jamie | GI3: Sam | GJ3: Jamie | GK3: Taylor | GL3: Alex | GM3: Jamie | GN3: Jamie | GO3: Jordan | GP3: Jordan | GQ3: Morgan | GR3: Casey | GS3: Taylor | GT3: Jamie | GU3: Drew | GV3: Jamie | GW3: Alex | GX3: Morgan | GY3: Casey | GZ3: Drew | HA3: Morgan | HB3: Sam | HC3: Casey | HD3: Jamie | HE3: Jamie | HF3: Casey | HG3: Jamie | HH3: Taylor | HI3: Casey | HJ3: Morgan | HK3: Casey | HL3: Drew | HM3: Jamie | HN3: Taylor | HO3: Taylor | HP3: Sam | HQ3: Morgan | HR3: Jordan | HS3: Jordan | HT3: Casey | HU3: Sam | HV3: Alex | HW3: Casey | HX3: Sam | HY3: Morgan | HZ3: Morgan | IA3: Morgan | IB3: Morgan | IC3: Morgan | ID3: Sam | IE3: Sam | IF3: Taylor | IG3: Drew | IH3: Jordan | II3: Jamie | IJ3: Morgan | IK3: Alex | IL3: Jamie | IM3: Sam | IN3: Alex | IO3: Alex | IP3: Alex | IQ3: Taylor | IR3: Sam | IS3: Alex | IT3: Morgan | IU3: Casey | IV3: Alex | IW3: Taylor | IX3: Jamie | IY3: Sam | IZ3: Drew | JA3: Taylor | JB3: Alex | JC3: Sam | JD3: Casey | JE3: Alex | JF3: Taylor | JG3: Jordan | JH3: Morgan | JI3: Drew | JJ3: Jamie | JK3: Taylor | JL3: Sam | JM3: Drew | JN3: Drew | JO3: Drew | JP3: Alex | JQ3: Morgan | JR3: Alex | JS3: Sam | JT3: Alex | JU3: Jordan | JV3: Morgan | JW3: Morgan | JX3: Sam | JY3: Jamie | JZ3: Jordan | KA3: Taylor | KB3: Alex | KC3: Casey | KD3: Alex | KE3: Drew | KF3: Alex | KG3: Taylor | KH3: Alex | KI3: Jordan | KJ3: Jordan | KK3: Morgan | KL3: Sam | KM3: Jamie | KN3: Casey | KO3: Drew | KP3: Alex | KQ3: Alex | KR3: Taylor | KS3: Sam | KT3: Jordan | KU3: Casey | KV3: Morgan | KW3: Jordan | KX3: Drew | KY3: Sam | KZ3: Drew | LA3: Jamie | LB3: Morgan | LC3: Jamie | LD3: Taylor | LE3: Drew | LF3: Taylor | LG3: Alex | LH3: Jamie | LI3: Sam | LJ3: Drew | LK3: Casey | LL3: Morgan | LM3: Jordan | LN3: Sam | LO3: Sam | LP3: Taylor | LQ3: Jamie | LR3: Drew | LS3: Drew | LT3: Alex | LU3: Alex | LV3: Morgan | LW3: Taylor | LX3: Sam | LY3: Drew | LZ3: Casey | MA3: Taylor | MB3: Morgan | MC3: Morgan | MD3: Taylor | ME3: Morgan | MF3: Taylor | MG3: Jordan | MH3: Taylor | MI3: Jamie | MJ3: Taylor | MK3: Morgan | ML3: Drew | MM3: Jamie | MN3: Morgan | MO3: Alex | MP3: Alex | MQ3: Drew | MR3: Drew | MS3: Jamie | MT3: Jordan | MU3: Drew | MV3: Alex | MW3: Taylor | MX3: Morgan | MY3: Alex | MZ3: Alex | NA3: Jordan | NB3: Jamie | NC3: Jamie | ND3: Sam | NE3: Jordan | NF3: Taylor | NG3: Jamie | NH3: Morgan | NI3: Drew | NJ3: Jordan | NK3: Drew | NL3: Alex | NM3: Morgan | NN3: Morgan | NO3: Alex | NP3: Jordan | NQ3: Alex | NR3: Drew | NS3: Sam | NT3: Morgan | NU3: Casey | NV3: Casey | NW3: Drew | NX3: Taylor | NY3: Jamie | NZ3: Alex | OA3: Alex | OB3: Taylor | OC3: Taylor | OD3: Drew | OE3: Drew | OF3: Taylor | OG3: Morgan | OH3: Drew | OI3: Sam | OJ3: Drew | OK3: Alex | OL3: Drew | OM3: Morgan | ON3: Taylor | OO3: Alex | OP3: Drew | OQ3: Morgan | OR3: Sam | OS3: Drew | OT3: Morgan | OU3: Sam | OV3: Taylor | OW3: Drew | OX3: Sam | OY3: Alex | OZ3: Taylor | PA3: Alex | PB3: Casey | PC3: Jordan | PD3: Drew | PE3: Sam | PF3: Jordan | PG3: Jordan | PH3: Sam | PI3: Taylor | PJ3: Drew | PK3: Casey | PL3: Alex | PM3: Morgan | PN3: Alex | PO3: Morgan | PP3: Alex | PQ3: Sam | PR3: Casey | PS3: Drew | PT3: Morgan | PU3: Drew | PV3: Drew | PW3: Drew | PX3: Jamie | PY3: Taylor | PZ3: Alex | QA3: Drew | QB3: Alex | QC3: Drew | QD3: Morgan | QE3: Taylor | QF3: Taylor | QG3: Sam | QH3: Jamie | QI3: Sam | QJ3: Sam | QK3: Sam | QL3: Sam | QM3: Sam | QN3: Casey | QO3: Taylor | QP3: Sam | QQ3: Drew | QR3: Taylor | QS3: Taylor | QT3: Jordan | QU3: Casey | QV3: Sam | QW3: Alex | QX3: Morgan | QY3: Jamie | QZ3: Drew | RA3: Alex | RB3: Casey | RC3: Morgan | RD3: Casey | RE3: Drew | RF3: Taylor | RG3: Morgan | RH3: Taylor | RI3: Drew | RJ3: Alex | RK3: Drew | RL3: Alex | RM3: Morgan | RN3: Morgan | RO3: Sam | RP3: Casey | RQ3: Sam | RR3: Casey | RS3: Sam | RT3: Taylor | RU3: Morgan | RV3: Alex | RW3: Casey | RX3: Drew | RY3: Casey | RZ3: Alex | SA3: Sam | SB3: Casey | SC3: Jamie | SD3: Taylor | SE3: Morgan | SF3: Alex | SG3: Morgan | SH3: Jamie | SI3: Casey | SJ3: Casey | SK3: Drew | SL3: Jamie | SM3: Alex | SN3: Drew | SO3: Taylor | SP3: Drew | SQ3: Jordan | SR3: Alex | SS3: Jordan | ST3: Jamie | SU3: Sam | SV3: Jordan | SW3: Taylor | SX3: Drew | SY3: Sam | SZ3: Drew | TA3: Jordan | TB3: Drew | TC3: Jamie | TD3: Sam | TE3: Jamie | TF3: Jordan | TG3: Jamie | TH3: Taylor | TI3: Jordan | TJ3: Jordan | TK3: Jordan | TL3: Alex | TM3: Drew | TN3: Alex | TO3: Alex | TP3: Taylor | TQ3: Sam | TR3: Drew | TS3: Jamie | TT3: Casey | TU3: Jordan | TV3: Jamie | TW3: Jordan | TX3: Taylor | TY3: Jordan | TZ3: Alex | UA3: Drew | UB3: Casey | UC3: Morgan | UD3: Jordan | UE3: Jamie | UF3: Alex | UG3: Morgan | UH3: Casey | UI3: Morgan | UJ3: Alex | UK3: Drew | UL3: Drew | UM3: Sam | UN3: Drew | UO3: Sam | UP3: Morgan | UQ3: Taylor | UR3: Jamie | US3: Jamie | UT3: Morgan | UU3: Jordan | UV3: Jordan | UW3: Drew | UX3: Jamie | UY3: Jamie | UZ3: Sam | VA3: Taylor | VB3: Alex | VC3: Jordan | VD3: Jamie | VE3: Sam | VF3: Casey | VG3: Sam | VH3: Jordan | VI3: Jordan | VJ3: Sam | VK3: Alex | VL3: Morgan | VM3: Jordan | VN3: Sam | VO3: Jamie | VP3: Sam | VQ3: Taylor | VR3: Morgan | VS3: Casey | VT3: Alex | VU3: Drew | VV3: Casey | VW3: Morgan | VX3: Morgan | VY3: Morgan | VZ3: Casey | WA3: Jamie | WB3: Morgan | WC3: Sam | WD3: Casey | WE3: Drew | WF3: Morgan | WG3: Sam | WH3: Jamie | WI3: Taylor | WJ3: Jamie | WK3: Drew | WL3: Morgan | WM3: Drew | WN3: Casey | WO3: Jordan | WP3: Morgan | WQ3: Jordan | WR3: Sam | WS3: Taylor | WT3: Alex | WU3: Drew | WV3: Jamie | WW3: Taylor | WX3: Morgan | WY3: Jordan | WZ3: Jamie | XA3: Jordan | XB3: Casey | XC3: Jordan | XD3: Casey | XE3: Sam | XF3: Jamie | XG3: Jamie | XH3: Alex | XI3: Morgan | XJ3: Casey | XK3: Alex | XL3: Jordan | XM3: Jordan | XN3: Alex | XO3: Jamie | XP3: Jordan | XQ3: Drew | XR3: Sam | XS3: Sam | XT3: Drew | XU3: Alex | XV3: Drew | XW3: Casey | XX3: Casey | XY3: Alex | XZ3: Drew | YA3: Casey | YB3: Jamie | YC3: Drew | YD3: Jamie | YE3: Casey | YF3: Sam | YG3: Casey | YH3: Jamie | YI3: Taylor | YJ3: Morgan | YK3: Jordan | YL3: Drew | YM3: Taylor | YN3: Casey | YO3: Sam | YP3: Alex | YQ3: Casey | YR3: Sam | YS3: Morgan | YT3: Casey | YU3: Jamie | YV3: Alex | YW3: Sam | YX3: Sam | YY3: Sam | YZ3: Morgan | ZA3: Casey | ZB3: Morgan | ZC3: Drew | ZD3: Jordan | ZE3: Jordan | ZF3: Drew | ZG3: Casey | ZH3: Jamie | ZI3: Morgan | ZJ3: Alex | ZK3: Sam | ZL3: Sam | ZM3: Casey | ZN3: Jamie | ZO3: Jordan | ZP3: Jordan | ZQ3: Sam | ZR3: Casey | ZS3: Morgan | ZT3: Jordan | ZU3: Morgan | ZV3: Jamie | ZW3: Jordan | ZX3: Jordan | ZY3: Taylor | ZZ3: Jordan | AAA3: Drew | AAB3: Alex | AAC3: Drew | AAD3: Casey | AAE3: Casey | AAF3: Morgan | AAG3: Drew | AAH3: Drew | AAI3: Drew | AAJ3: Jamie | AAK3: Jordan | AAL3: Alex | AAM3: Morgan | AAN3: Drew | AAO3: Drew | AAP3: Taylor | AAQ3: Morgan | AAR3: Drew | AAS3: Morgan | AAT3: Jordan | AAU3: Taylor | AAV3: Morgan | AAW3: Alex | AAX3: Alex | AAY3: Casey | AAZ3: Taylor | ABA3: Taylor | ABB3: Casey | ABC3: Morgan | ABD3: Taylor | ABE3: Alex | ABF3: Alex | ABG3: Drew | ABH3: Jordan | ABI3: Taylor | ABJ3: Morgan | ABK3: Casey | ABL3: Casey | ABM3: Morgan | ABN3: Jamie | ABO3: Sam | ABP3: Jordan | ABQ3: Casey | ABR3: Taylor | ABS3: Jordan | ABT3: Taylor | ABU3: Jamie | ABV3: Alex | ABW3: Jordan | ABX3: Drew | ABY3: Casey | ABZ3: Jordan | ACA3: Jordan | ACB3: Jordan | ACC3: Sam | ACD3: Jordan | ACE3: Taylor | ACF3: Alex | ACG3: Jamie | ACH3: Morgan | ACI3: Jordan | ACJ3: Casey | ACK3: Jordan | ACL3: Casey | ACM3: Taylor | ACN3: Casey | ACO3: Drew | ACP3: Morgan | ACQ3: Alex | ACR3: Casey | ACS3: Casey | ACT3: Alex | ACU3: Morgan | ACV3: Jordan | ACW3: Casey | ACX3: Alex | ACY3: Drew | ACZ3: Drew | ADA3: Taylor | ADB3: Alex | ADC3: Taylor | ADD3: Drew | ADE3: Morgan | ADF3: Jordan | ADG3: Alex | ADH3: Jamie | ADI3: Drew | ADJ3: Drew | ADK3: Jamie | ADL3: Sam | ADM3: Drew | ADN3: Casey | ADO3: Morgan | ADP3: Alex | ADQ3: Jamie | ADR3: Casey | ADS3: Jamie | ADT3: Alex | ADU3: Taylor | ADV3: Alex | ADW3: Sam | ADX3: Alex | ADY3: Alex | ADZ3: Sam | AEA3: Morgan | AEB3: Drew | AEC3: Alex | AED3: Sam | AEE3: Casey | AEF3: Taylor | AEG3: Taylor | AEH3: Alex | AEI3: Morgan | AEJ3: Morgan | AEK3: Casey | AEL3: Alex | AEM3: Taylor | AEN3: Morgan | AEO3: Alex | AEP3: Jamie | AEQ3: Morgan | AER3: Sam | AES3: Jamie | AET3: Drew | AEU3: Morgan | AEV3: Taylor | AEW3: Jordan | AEX3: Jamie | AEY3: Drew | AEZ3: Casey | AFA3: Casey | AFB3: Taylor | AFC3: Morgan | AFD3: Alex | AFE3: Morgan | AFF3: Taylor | AFG3: Casey | AFH3: Morgan | AFI3: Casey | AFJ3: Jamie | AFK3: Drew | AFL3: Alex | AFM3: Jamie | AFN3: Casey | AFO3: Casey | AFP3: Jordan | AFQ3: Jordan | AFR3: Jamie | AFS3: Sam | AFT3: Jamie | AFU3: Jordan | AFV3: Casey | AFW3: Taylor | AFX3: Jamie | AFY3: Casey | AFZ3: Taylor | AGA3: Taylor | AGB3: Jordan | AGC3: Jamie | AGD3: Morgan | AGE3: Alex | AGF3: Jordan | AGG3: Jordan | AGH3: Morgan | AGI3: Alex | AGJ3: Casey | AGK3: Sam | AGL3: Jamie | AGM3: Sam | AGN3: Casey | AGO3: Drew | AGP3: Jordan | AGQ3: Alex | AGR3: Jordan | AGS3: Taylor | AGT3: Jordan | AGU3: Jordan | AGV3: Casey | AGW3: Casey | AGX3: Casey | AGY3: Sam | AGZ3: Taylor | AHA3: Drew | AHB3: Drew | AHC3: Casey | AHD3: Alex | AHE3: Sam | AHF3: Morgan | AHG3: Alex | AHH3: Jamie | AHI3: Jamie | AHJ3: Alex | AHK3: Casey | AHL3: Morgan | AHM3: Morgan | AHN3: Sam | AHO3: Morgan | AHP3: Jamie | AHQ3: Taylor | AHR3: Casey | AHS3: Morgan | AHT3: Sam | AHU3: Jamie | AHV3: Taylor | AHW3: Jordan | AHX3: Jordan | AHY3: Taylor | AHZ3: Jamie | AIA3: Sam | AIB3: Taylor | AIC3: Casey | AID3: Casey | AIE3: Jordan | AIF3: Morgan | AIG3: Sam | AIH3: Jordan | AII3: Morgan | AIJ3: Morgan | AIK3: Drew | AIL3: Casey | AIM3: Jamie | AIN3: Alex | AIO3: Jamie | AIP3: Alex | AIQ3: Taylor | AIR3: Casey | AIS3: Morgan | AIT3: Sam | AIU3: Alex | AIV3: Jamie | AIW3: Morgan | AIX3: Alex | AIY3: Alex | AIZ3: Drew | AJA3: Alex | AJB3: Sam | AJC3: Casey | AJD3: Sam | AJE3: Jordan | AJF3: Morgan | AJG3: Casey | AJH3: Drew | AJI3: Casey | AJJ3: Casey | AJK3: Jamie | AJL3: Casey | AJM3: Drew | AJN3: Sam | AJO3: Casey | AJP3: Taylor | AJQ3: Morgan | AJR3: Casey | AJS3: Morgan | AJT3: Taylor | AJU3: Taylor | AJV3: Morgan | AJW3: Alex | AJX3: Jordan | AJY3: Jamie | AJZ3: Alex | AKA3: Alex | AKB3: Sam | AKC3: Jamie | AKD3: Jamie | AKE3: Alex | AKF3: Casey | AKG3: Sam | AKH3: Sam | AKI3: Taylor | AKJ3: Drew | AKK3: Jamie | AKL3: Alex | AKM3: Taylor | AKN3: Morgan | AKO3: Jordan | AKP3: Drew | AKQ3: Drew | AKR3: Drew | AKS3: Sam | AKT3: Morgan | AKU3: Drew | AKV3: Morgan | AKW3: Casey | AKX3: Drew | AKY3: Jordan | AKZ3: Morgan | ALA3: Morgan | ALB3: Jordan | ALC3: Drew | ALD3: Jordan | ALE3: Morgan | ALF3: Jordan | ALG3: Morgan | ALH3: Morgan | ALI3: Casey | ALJ3: Alex | ALK3: Morgan | ALL3: Drew | ALM3: Taylor
